Traceback (most recent call last):
  File "C:\Users\yla\AppData\Local\anaconda3\lib\site-packages\jupyter_cache\executors\utils.py", line 58, in single_nb_execution
    executenb(
  File "C:\Users\yla\AppData\Local\anaconda3\lib\site-packages\nbclient\client.py", line 1204, in execute
    return NotebookClient(nb=nb, resources=resources, km=km, **kwargs).execute()
  File "C:\Users\yla\AppData\Local\anaconda3\lib\site-packages\nbclient\util.py", line 84, in wrapped
    return just_run(coro(*args, **kwargs))
  File "C:\Users\yla\AppData\Local\anaconda3\lib\site-packages\nbclient\util.py", line 62, in just_run
    return loop.run_until_complete(coro)
  File "C:\Users\yla\AppData\Local\anaconda3\lib\asyncio\base_events.py", line 649, in run_until_complete
    return future.result()
  File "C:\Users\yla\AppData\Local\anaconda3\lib\site-packages\nbclient\client.py", line 663, in async_execute
    await self.async_execute_cell(
  File "C:\Users\yla\AppData\Local\anaconda3\lib\site-packages\nbclient\client.py", line 965, in async_execute_cell
    await self._check_raise_for_error(cell, cell_index, exec_reply)
  File "C:\Users\yla\AppData\Local\anaconda3\lib\site-packages\nbclient\client.py", line 862, in _check_raise_for_error
    raise CellExecutionError.from_cell_and_msg(cell, exec_reply_content)
nbclient.exceptions.CellExecutionError: An error occurred while executing the following cell:
------------------
newexp = Acquisition(exe_path = r"C:\Users\Asylum User\Desktop\Yongtao_Desktop\BEPyAE 060523 01\BEPyAE.exe")   
# exe_path is the directory of BEPyAE; 
------------------

[1;31m---------------------------------------------------------------------------[0m
[1;31mFileNotFoundError[0m                         Traceback (most recent call last)
Cell [1;32mIn[2], line 1[0m
[1;32m----> 1[0m newexp [38;5;241m=[39m [43mAcquisition[49m[43m([49m[43mexe_path[49m[43m [49m[38;5;241;43m=[39;49m[43m [49m[38;5;124;43mr[39;49m[38;5;124;43m"[39;49m[38;5;124;43mC:[39;49m[38;5;124;43m\[39;49m[38;5;124;43mUsers[39;49m[38;5;124;43m\[39;49m[38;5;124;43mAsylum User[39;49m[38;5;124;43m\[39;49m[38;5;124;43mDesktop[39;49m[38;5;124;43m\[39;49m[38;5;124;43mYongtao_Desktop[39;49m[38;5;124;43m\[39;49m[38;5;124;43mBEPyAE 060523 01[39;49m[38;5;124;43m\[39;49m[38;5;124;43mBEPyAE.exe[39;49m[38;5;124;43m"[39;49m[43m)[49m

File [1;32m~\Aecroscopy_local\Acquisition_v0_9.py:32[0m, in [0;36mAcquisition.__init__[1;34m(self, exe_path, client, pyae_vi, pyscanner_vi)[0m
[0;32m     21[0m [38;5;124;03m"""[39;00m
[0;32m     22[0m [38;5;124;03mInitializes the Acquistion class and starts BEPyAE.exe.[39;00m
[0;32m     23[0m 
[1;32m   (...)[0m
[0;32m     28[0m [38;5;124;03m    pyscanner_vi (str): Path to the Pyscanner VI.[39;00m
[0;32m     29[0m [38;5;124;03m"""[39;00m 
[0;32m     31[0m [38;5;66;03m# Start BEPyAE[39;00m
[1;32m---> 32[0m [43mos[49m[38;5;241;43m.[39;49m[43mstartfile[49m[43m([49m[43mexe_path[49m[43m)[49m
[0;32m     34[0m [38;5;66;03m# Wait until BEPyAE.exe starts, then set VI reference 'BEPyAE.vi'[39;00m
[0;32m     35[0m bepyae_not_start [38;5;241m=[39m [38;5;28;01mTrue[39;00m

[1;31mFileNotFoundError[0m: [WinError 2] The system cannot find the file specified: 'C:\\Users\\Asylum User\\Desktop\\Yongtao_Desktop\\BEPyAE 060523 01\\BEPyAE.exe'
FileNotFoundError: [WinError 2] The system cannot find the file specified: 'C:\\Users\\Asylum User\\Desktop\\Yongtao_Desktop\\BEPyAE 060523 01\\BEPyAE.exe'

