Traceback (most recent call last):
  File "C:\Users\yla\AppData\Local\anaconda3\lib\site-packages\jupyter_cache\executors\utils.py", line 58, in single_nb_execution
    executenb(
  File "C:\Users\yla\AppData\Local\anaconda3\lib\site-packages\nbclient\client.py", line 1204, in execute
    return NotebookClient(nb=nb, resources=resources, km=km, **kwargs).execute()
  File "C:\Users\yla\AppData\Local\anaconda3\lib\site-packages\nbclient\util.py", line 84, in wrapped
    return just_run(coro(*args, **kwargs))
  File "C:\Users\yla\AppData\Local\anaconda3\lib\site-packages\nbclient\util.py", line 62, in just_run
    return loop.run_until_complete(coro)
  File "C:\Users\yla\AppData\Local\anaconda3\lib\asyncio\base_events.py", line 649, in run_until_complete
    return future.result()
  File "C:\Users\yla\AppData\Local\anaconda3\lib\site-packages\nbclient\client.py", line 663, in async_execute
    await self.async_execute_cell(
  File "C:\Users\yla\AppData\Local\anaconda3\lib\site-packages\nbclient\client.py", line 965, in async_execute_cell
    await self._check_raise_for_error(cell, cell_index, exec_reply)
  File "C:\Users\yla\AppData\Local\anaconda3\lib\site-packages\nbclient\client.py", line 862, in _check_raise_for_error
    raise CellExecutionError.from_cell_and_msg(cell, exec_reply_content)
nbclient.exceptions.CellExecutionError: An error occurred while executing the following cell:
------------------
import os
import win32com.client
import numpy as np
import time
import h5py
import sidpy
import pyNSID
import matplotlib.pyplot as plt
from tqdm import tqdm

# import acquition.py
from Acquisition_v0_5 import Acquisition   # include the Acquistion_v0.py in the same directory


import cv2
# import imutils
from os.path import exists
# from jupyterthemes import jtplot
# jtplot.style()
------------------

[1;31m---------------------------------------------------------------------------[0m
[1;31mModuleNotFoundError[0m                       Traceback (most recent call last)
Cell [1;32mIn[1], line 12[0m
[0;32m      9[0m [38;5;28;01mfrom[39;00m [38;5;21;01mtqdm[39;00m [38;5;28;01mimport[39;00m tqdm
[0;32m     11[0m [38;5;66;03m# import acquition.py[39;00m
[1;32m---> 12[0m [38;5;28;01mfrom[39;00m [38;5;21;01mAcquisition_v0_5[39;00m [38;5;28;01mimport[39;00m Acquisition   [38;5;66;03m# include the Acquistion_v0.py in the same directory[39;00m
[0;32m     15[0m [38;5;28;01mimport[39;00m [38;5;21;01mcv2[39;00m
[0;32m     16[0m [38;5;66;03m# import imutils[39;00m

[1;31mModuleNotFoundError[0m: No module named 'Acquisition_v0_5'
ModuleNotFoundError: No module named 'Acquisition_v0_5'

